<?xml version="1.0" encoding="UTF-8"?>
<!-- Generated by org.testng.reporters.JUnitReportReporter -->
<testsuite hostname="DAN-PC" name="com.extent.testExtentReport" tests="4" failures="1" timestamp="3 May 2019 16:40:11 GMT" time="0.007" errors="1">
  <testcase name="test3" time="0.000" classname="com.extent.testExtentReport"/>
  <testcase name="test1" time="0.006" classname="com.extent.testExtentReport"/>
  <testcase name="test4" time="0.000" classname="com.extent.testExtentReport">
    <error type="java.lang.RuntimeException" message="this is exception by myself">
      <![CDATA[java.lang.RuntimeException: this is exception by myself
	at com.extent.testExtentReport.test4(testExtentReport.java:27)
	at sun.reflect.NativeMethodAccessorImpl.invoke0(Native Method)
	at sun.reflect.NativeMethodAccessorImpl.invoke(NativeMethodAccessorImpl.java:62)
	at sun.reflect.DelegatingMethodAccessorImpl.invoke(DelegatingMethodAccessorImpl.java:43)
	at java.lang.reflect.Method.invoke(Method.java:498)
	at org.testng.internal.MethodInvocationHelper.invokeMethod(MethodInvocationHelper.java:85)
	at org.testng.internal.Invoker.invokeMethod(Invoker.java:639)
	at org.testng.internal.Invoker.invokeTestMethod(Invoker.java:821)
	at org.testng.internal.Invoker.invokeTestMethods(Invoker.java:1131)
	at org.testng.internal.TestMethodWorker.invokeTestMethods(TestMethodWorker.java:124)
	at org.testng.internal.TestMethodWorker.run(TestMethodWorker.java:108)
	at org.testng.TestRunner.privateRun(TestRunner.java:773)
	at org.testng.TestRunner.run(TestRunner.java:623)
	at org.testng.SuiteRunner.runTest(SuiteRunner.java:357)
	at org.testng.SuiteRunner.runSequentially(SuiteRunner.java:352)
	at org.testng.SuiteRunner.privateRun(SuiteRunner.java:310)
	at org.testng.SuiteRunner.run(SuiteRunner.java:259)
	at org.testng.SuiteRunnerWorker.runSuite(SuiteRunnerWorker.java:52)
	at org.testng.SuiteRunnerWorker.run(SuiteRunnerWorker.java:86)
	at org.testng.TestNG.runSuitesSequentially(TestNG.java:1185)
	at org.testng.TestNG.runSuitesLocally(TestNG.java:1110)
	at org.testng.TestNG.run(TestNG.java:1018)
	at org.apache.maven.surefire.testng.TestNGExecutor.run(TestNGExecutor.java:74)
	at org.apache.maven.surefire.testng.TestNGXmlTestSuite.execute(TestNGXmlTestSuite.java:93)
	at org.apache.maven.surefire.testng.TestNGProvider.invoke(TestNGProvider.java:101)
	at sun.reflect.NativeMethodAccessorImpl.invoke0(Native Method)
	at sun.reflect.NativeMethodAccessorImpl.invoke(NativeMethodAccessorImpl.java:62)
	at sun.reflect.DelegatingMethodAccessorImpl.invoke(DelegatingMethodAccessorImpl.java:43)
	at java.lang.reflect.Method.invoke(Method.java:498)
	at org.apache.maven.surefire.booter.ProviderFactory$ClassLoaderProxy.invoke(ProviderFactory.java:103)
	at com.sun.proxy.$Proxy0.invoke(Unknown Source)
	at org.apache.maven.surefire.booter.SurefireStarter.invokeProvider(SurefireStarter.java:145)
	at org.apache.maven.surefire.booter.SurefireStarter.runSuitesInProcess(SurefireStarter.java:87)
	at org.apache.maven.surefire.booter.ForkedBooter.main(ForkedBooter.java:69)
]]>
    </error>
  </testcase> <!-- test4 -->
  <testcase name="test2" time="0.001" classname="com.extent.testExtentReport">
    <failure type="java.lang.AssertionError" message="test2 expected [2] but found [1]">
      <![CDATA[java.lang.AssertionError: test2 expected [2] but found [1]
	at org.testng.Assert.fail(Assert.java:94)
	at org.testng.Assert.failNotEquals(Assert.java:496)
	at org.testng.Assert.assertEquals(Assert.java:125)
	at org.testng.Assert.assertEquals(Assert.java:372)
	at com.extent.testExtentReport.test2(testExtentReport.java:16)
	at sun.reflect.NativeMethodAccessorImpl.invoke0(Native Method)
	at sun.reflect.NativeMethodAccessorImpl.invoke(NativeMethodAccessorImpl.java:62)
	at sun.reflect.DelegatingMethodAccessorImpl.invoke(DelegatingMethodAccessorImpl.java:43)
	at java.lang.reflect.Method.invoke(Method.java:498)
	at org.testng.internal.MethodInvocationHelper.invokeMethod(MethodInvocationHelper.java:85)
	at org.testng.internal.Invoker.invokeMethod(Invoker.java:639)
	at org.testng.internal.Invoker.invokeTestMethod(Invoker.java:821)
	at org.testng.internal.Invoker.invokeTestMethods(Invoker.java:1131)
	at org.testng.internal.TestMethodWorker.invokeTestMethods(TestMethodWorker.java:124)
	at org.testng.internal.TestMethodWorker.run(TestMethodWorker.java:108)
	at org.testng.TestRunner.privateRun(TestRunner.java:773)
	at org.testng.TestRunner.run(TestRunner.java:623)
	at org.testng.SuiteRunner.runTest(SuiteRunner.java:357)
	at org.testng.SuiteRunner.runSequentially(SuiteRunner.java:352)
	at org.testng.SuiteRunner.privateRun(SuiteRunner.java:310)
	at org.testng.SuiteRunner.run(SuiteRunner.java:259)
	at org.testng.SuiteRunnerWorker.runSuite(SuiteRunnerWorker.java:52)
	at org.testng.SuiteRunnerWorker.run(SuiteRunnerWorker.java:86)
	at org.testng.TestNG.runSuitesSequentially(TestNG.java:1185)
	at org.testng.TestNG.runSuitesLocally(TestNG.java:1110)
	at org.testng.TestNG.run(TestNG.java:1018)
	at org.apache.maven.surefire.testng.TestNGExecutor.run(TestNGExecutor.java:74)
	at org.apache.maven.surefire.testng.TestNGXmlTestSuite.execute(TestNGXmlTestSuite.java:93)
	at org.apache.maven.surefire.testng.TestNGProvider.invoke(TestNGProvider.java:101)
	at sun.reflect.NativeMethodAccessorImpl.invoke0(Native Method)
	at sun.reflect.NativeMethodAccessorImpl.invoke(NativeMethodAccessorImpl.java:62)
	at sun.reflect.DelegatingMethodAccessorImpl.invoke(DelegatingMethodAccessorImpl.java:43)
	at java.lang.reflect.Method.invoke(Method.java:498)
	at org.apache.maven.surefire.booter.ProviderFactory$ClassLoaderProxy.invoke(ProviderFactory.java:103)
	at com.sun.proxy.$Proxy0.invoke(Unknown Source)
	at org.apache.maven.surefire.booter.SurefireStarter.invokeProvider(SurefireStarter.java:145)
	at org.apache.maven.surefire.booter.SurefireStarter.runSuitesInProcess(SurefireStarter.java:87)
	at org.apache.maven.surefire.booter.ForkedBooter.main(ForkedBooter.java:69)
]]>
    </failure>
  </testcase> <!-- test2 -->
</testsuite> <!-- com.extent.testExtentReport -->
