<?xml version="1.0" encoding="UTF-8"?>
<!-- Generated by org.testng.reporters.JUnitXMLReporter -->
<testsuite hostname="DAN-PC" name="extentreport" tests="4" failures="2" timestamp="3 May 2019 16:40:11 GMT" time="0.032" errors="0">
  <testcase name="test1" time="0.006" classname="com.extent.testExtentReport"/>
  <testcase name="test2" time="0.001" classname="com.extent.testExtentReport">
    <failure type="java.lang.AssertionError" message="test2 expected [2] but found [1]">
      <![CDATA[java.lang.AssertionError: test2 expected [2] but found [1]
	at com.extent.testExtentReport.test2(testExtentReport.java:16)
	at com.sun.proxy.$Proxy0.invoke(Unknown Source)
... Removed 36 stack frames]]>
    </failure>
  </testcase> <!-- test2 -->
  <testcase name="test3" time="0.0" classname="com.extent.testExtentReport"/>
  <testcase name="test4" time="0.0" classname="com.extent.testExtentReport">
    <failure type="java.lang.RuntimeException" message="this is exception by myself">
      <![CDATA[java.lang.RuntimeException: this is exception by myself
	at com.extent.testExtentReport.test4(testExtentReport.java:27)
	at com.sun.proxy.$Proxy0.invoke(Unknown Source)
... Removed 32 stack frames]]>
    </failure>
  </testcase> <!-- test4 -->
</testsuite> <!-- extentreport -->
